[01/23/2019 10:00:13 AM] INFO:Starting to process `mylist`...
[01/23/2019 10:00:13 AM] DEBUG:Value at position 0 is 1
[01/23/2019 10:00:13 AM] DEBUG:Value at position 1 is 2
[01/23/2019 10:00:13 AM] DEBUG:Value at position 2 is 3
[01/23/2019 10:00:13 AM] ERROR:Faulty position: 3
Traceback (most recent call last):
  File "log.py", line 9, in <module>
    logging.debug('Value at position {} is {}'.format(position, mylist[position]))
IndexError: list index out of range
[01/23/2019 10:00:13 AM] INFO:Done parsing `mylist`.
